Workbook
Name categories: categories!$A$1:$C$9
Name customers: customers!$A$1:$F$92
Name employees: employees!$A$1:$F$10
Name orders: orders!$A$1:$H$831
Name products: products!$A$1:$F$78
Name shippers: shippers!$A$1:$B$4
Name Slicer_Category: #N/A
Name Slicer_Country: #N/A
Name Slicer_Year: #N/A

Sheet orders
A1: orderID | B1: customerID | C1: employeeID | D1: orderDate | E1: requiredDate | F1: shippedDate | G1: shipperID | H1: freight | I1: Year
A2: 10248 | B2: VINET | C2: 5 | D2: 41459 | E2: 41487 | F2: 41471 | G2: 3 | H2: 32.38 | I2: =YEAR(D2) -> 2013
A3: 10249 | B3: TOMSP | C3: 6 | D3: 41460 | E3: 41502 | F3: 41465 | G3: 1 | H3: 11.61 | I3: =YEAR(D3) -> 2013
A4: 10250 | B4: HANAR | C4: 4 | D4: 41463 | E4: 41491 | F4: 41467 | G4: 2 | H4: 65.83 | I4: =YEAR(D4) -> 2013
A5: 10251 | B5: VICTE | C5: 3 | D5: 41463 | E5: 41491 | F5: 41470 | G5: 1 | H5: 41.34 | I5: =YEAR(D5) -> 2013
A6: 10252 | B6: SUPRD | C6: 4 | D6: 41464 | E6: 41492 | F6: 41466 | G6: 2 | H6: 51.3 | I6: =YEAR(D6) -> 2013
A7: 10253 | B7: HANAR | C7: 3 | D7: 41465 | E7: 41479 | F7: 41471 | G7: 2 | H7: 58.17 | I7: =YEAR(D7) -> 2013
A8: 10254 | B8: CHOPS | C8: 5 | D8: 41466 | E8: 41494 | F8: 41478 | G8: 2 | H8: 22.98 | I8: =YEAR(D8) -> 2013
A9: 10255 | B9: RICSU | C9: 9 | D9: 41467 | E9: 41495 | F9: 41470 | G9: 3 | H9: 148.33 | I9: =YEAR(D9) -> 2013
A10: 10256 | B10: WELLI | C10: 3 | D10: 41470 | E10: 41498 | F10: 41472 | G10: 2 | H10: 13.97 | I10: =YEAR(D10) -> 2013
A11: 10257 | B11: HILAA | C11: 4 | D11: 41471 | E11: 41499 | F11: 41477 | G11: 3 | H11: 81.91 | I11: =YEAR(D11) -> 2013
A12: 10258 | B12: ERNSH | C12: 1 | D12: 41472 | E12: 41500 | F12: 41478 | G12: 1 | H12: 140.51 | I12: =YEAR(D12) -> 2013
A13: 10259 | B13: CENTC | C13: 4 | D13: 41473 | E13: 41501 | F13: 41480 | G13: 3 | H13: 3.25 | I13: =YEAR(D13) -> 2013
... A761: 11007 | B761: PRINI | C761: 8 | D761: 42102 | E761: 42130 | F761: 42107 | G761: 2 | H761: 202.24 | I761: =YEAR(D761) -> 2015
A762: 11008 | B762: ERNSH | C762: 7 | D762: 42102 | E762: 42130 | G762: 3 | H762: 79.46 | I762: =YEAR(D762) -> 2015
A763: 11009 | B763: GODOS | C763: 2 | D763: 42102 | E763: 42130 | F763: 42104 | G763: 1 | H763: 59.11 | I763: =YEAR(D763) -> 2015
A764: 11010 | B764: REGGC | C764: 2 | D764: 42103 | E764: 42131 | F764: 42115 | G764: 2 | H764: 28.71 | I764: =YEAR(D764) -> 2015
A765: 11011 | B765: ALFKI | C765: 3 | D765: 42103 | E765: 42131 | F765: 42107 | G765: 1 | H765: 1.21 | I765: =YEAR(D765) -> 2015
A766: 11012 | B766: FRANK | C766: 1 | D766: 42103 | E766: 42117 | F766: 42111 | G766: 3 | H766: 242.95 | I766: =YEAR(D766) -> 2015
A767: 11013 | B767: ROMEY | C767: 2 | D767: 42103 | E767: 42131 | F767: 42104 | G767: 1 | H767: 32.99 | I767: =YEAR(D767) -> 2015
A768: 11014 | B768: LINOD | C768: 2 | D768: 42104 | E768: 42132 | F768: 42109 | G768: 3 | H768: 23.6 | I768: =YEAR(D768) -> 2015
A769: 11015 | B769: SANTG | C769: 2 | D769: 42104 | E769: 42118 | F769: 42114 | G769: 2 | H769: 4.62 | I769: =YEAR(D769) -> 2015
A770: 11016 | B770: AROUT | C770: 9 | D770: 42104 | E770: 42132 | F770: 42107 | G770: 2 | H770: 33.8 | I770: =YEAR(D770) -> 2015
A771: 11017 | B771: ERNSH | C771: 9 | D771: 42107 | E771: 42135 | F771: 42114 | G771: 2 | H771: 754.26 | I771: =YEAR(D771) -> 2015
A772: 11018 | B772: LONEP | C772: 4 | D772: 42107 | E772: 42135 | F772: 42110 | G772: 2 | H772: 11.65 | I772: =YEAR(D772) -> 2015
A773: 11019 | B773: RANCH | C773: 6 | D773: 42107 | E773: 42135 | G773: 3 | H773: 3.17 | I773: =YEAR(D773) -> 2015
A774: 11020 | B774: OTTIK | C774: 2 | D774: 42108 | E774: 42136 | F774: 42110 | G774: 2 | H774: 43.3 | I774: =YEAR(D774) -> 2015
A775: 11021 | B775: QUICK | C775: 3 | D775: 42108 | E775: 42136 | F775: 42115 | G775: 1 | H775: 297.18 | I775: =YEAR(D775) -> 2015
A776: 11022 | B776: HANAR | C776: 9 | D776: 42108 | E776: 42136 | F776: 42128 | G776: 2 | H776: 6.27 | I776: =YEAR(D776) -> 2015
A777: 11023 | B777: BSBEV | C777: 1 | D777: 42108 | E777: 42122 | F777: 42118 | G777: 2 | H777: 123.83 | I777: =YEAR(D777) -> 2015
A778: 11024 | B778: EASTC | C778: 4 | D778: 42109 | E778: 42137 | F778: 42114 | G778: 1 | H778: 74.36 | I778: =YEAR(D778) -> 2015
A779: 11025 | B779: WARTH | C779: 6 | D779: 42109 | E779: 42137 | F779: 42118 | G779: 3 | H779: 29.17 | I779: =YEAR(D779) -> 2015
A780: 11026 | B780: FRANS | C780: 4 | D780: 42109 | E780: 42137 | F780: 42122 | G780: 1 | H780: 47.09 | I780: =YEAR(D780) -> 2015
A781: 11027 | B781: BOTTM | C781: 1 | D781: 42110 | E781: 42138 | F781: 42114 | G781: 1 | H781: 52.52 | I781: =YEAR(D781) -> 2015
A782: 11028 | B782: KOENE | C782: 2 | D782: 42110 | E782: 42138 | F782: 42116 | G782: 1 | H782: 29.59 | I782: =YEAR(D782) -> 2015
A783: 11029 | B783: CHOPS | C783: 4 | D783: 42110 | E783: 42138 | F783: 42121 | G783: 1 | H783: 47.84 | I783: =YEAR(D783) -> 2015
A784: 11030 | B784: SAVEA | C784: 7 | D784: 42111 | E784: 42139 | F784: 42121 | G784: 2 | H784: 830.75 | I784: =YEAR(D784) -> 2015
A785: 11031 | B785: SAVEA | C785: 6 | D785: 42111 | E785: 42139 | F785: 42118 | G785: 2 | H785: 227.22 | I785: =YEAR(D785) -> 2015
... A792: 11038 | B792: SUPRD | C792: 1 | D792: 42115 | E792: 42143 | F792: 42124 | G792: 2 | H792: 29.59 | I792: =YEAR(D792) -> 2015
A793: 11039 | B793: LINOD | C793: 1 | D793: 42115 | E793: 42143 | G793: 2 | H793: 65 | I793: =YEAR(D793) -> 2015
...

Sheet order_details
A1: orderID | B1: productID | C1: unitPrice | D1: quantity | E1: discount | F1: Revenue | G1: Year | H1: Month | I1: Category | J1: Country | K1: Employee
A2: 10248 | B2: 11 | C2: 14 | D2: 12 | E2: 0 | F2: =C2*D2*(1-E2) -> 168 | G2: =YEAR(VLOOKUP(A2,orders!A:D,4,0)) -> 2013 | H2: =MONTH(INDEX(orders!D:D,MATCH(A2, orders!A:A,0))) -> 7 | I2: =VLOOKUP(VLOOKUP(B2,products!A:F,6,0),categories!A:B,2,0) -> Dairy Products | J2: =VLOOKUP(VLOOKUP(A2,orders!A:B,2,0),customers!A:F,6,0) -> France | K2: =VLOOKUP(VLOOKUP(A2,orders!A:C,3,0),employees!A:B,2,0) -> Steven Buchanan
A3: 10248 | B3: 42 | C3: 9.8 | D3: 10 | E3: 0 | F3: =C3*D3*(1-E3) -> 98 | G3: =YEAR(VLOOKUP(A3,orders!A:D,4,0)) -> 2013 | H3: =MONTH(INDEX(orders!D:D,MATCH(A3, orders!A:A,0))) -> 7 | I3: =VLOOKUP(VLOOKUP(B3,products!A:F,6,0),categories!A:B,2,0) -> Grains & Cereals | J3: =VLOOKUP(VLOOKUP(A3,orders!A:B,2,0),customers!A:F,6,0) -> France | K3: =VLOOKUP(VLOOKUP(A3,orders!A:C,3,0),employees!A:B,2,0) -> Steven Buchanan
A4: 10248 | B4: 72 | C4: 34.8 | D4: 5 | E4: 0 | F4: =C4*D4*(1-E4) -> 174 | G4: =YEAR(VLOOKUP(A4,orders!A:D,4,0)) -> 2013 | H4: =MONTH(INDEX(orders!D:D,MATCH(A4, orders!A:A,0))) -> 7 | I4: =VLOOKUP(VLOOKUP(B4,products!A:F,6,0),categories!A:B,2,0) -> Dairy Products | J4: =VLOOKUP(VLOOKUP(A4,orders!A:B,2,0),customers!A:F,6,0) -> France | K4: =VLOOKUP(VLOOKUP(A4,orders!A:C,3,0),employees!A:B,2,0) -> Steven Buchanan
A5: 10249 | B5: 14 | C5: 18.6 | D5: 9 | E5: 0 | F5: =C5*D5*(1-E5) -> 167.4 | G5: =YEAR(VLOOKUP(A5,orders!A:D,4,0)) -> 2013 | H5: =MONTH(INDEX(orders!D:D,MATCH(A5, orders!A:A,0))) -> 7 | I5: =VLOOKUP(VLOOKUP(B5,products!A:F,6,0),categories!A:B,2,0) -> Produce | J5: =VLOOKUP(VLOOKUP(A5,orders!A:B,2,0),customers!A:F,6,0) -> Germany | K5: =VLOOKUP(VLOOKUP(A5,orders!A:C,3,0),employees!A:B,2,0) -> Michael Suyama
A6: 10249 | B6: 51 | C6: 42.4 | D6: 40 | E6: 0 | F6: =C6*D6*(1-E6) -> 1696 | G6: =YEAR(VLOOKUP(A6,orders!A:D,4,0)) -> 2013 | H6: =MONTH(INDEX(orders!D:D,MATCH(A6, orders!A:A,0))) -> 7 | I6: =VLOOKUP(VLOOKUP(B6,products!A:F,6,0),categories!A:B,2,0) -> Produce | J6: =VLOOKUP(VLOOKUP(A6,orders!A:B,2,0),customers!A:F,6,0) -> Germany | K6: =VLOOKUP(VLOOKUP(A6,orders!A:C,3,0),employees!A:B,2,0) -> Michael Suyama
A7: 10250 | B7: 41 | C7: 7.7 | D7: 10 | E7: 0 | F7: =C7*D7*(1-E7) -> 77 | G7: =YEAR(VLOOKUP(A7,orders!A:D,4,0)) -> 2013 | H7: =MONTH(INDEX(orders!D:D,MATCH(A7, orders!A:A,0))) -> 7 | I7: =VLOOKUP(VLOOKUP(B7,products!A:F,6,0),categories!A:B,2,0) -> Seafood | J7: =VLOOKUP(VLOOKUP(A7,orders!A:B,2,0),customers!A:F,6,0) -> Brazil | K7: =VLOOKUP(VLOOKUP(A7,orders!A:C,3,0),employees!A:B,2,0) -> Margaret Peacock
A8: 10250 | B8: 51 | C8: 42.4 | D8: 35 | E8: 0.15 | F8: =C8*D8*(1-E8) -> 1261.4 | G8: =YEAR(VLOOKUP(A8,orders!A:D,4,0)) -> 2013 | H8: =MONTH(INDEX(orders!D:D,MATCH(A8, orders!A:A,0))) -> 7 | I8: =VLOOKUP(VLOOKUP(B8,products!A:F,6,0),categories!A:B,2,0) -> Produce | J8: =VLOOKUP(VLOOKUP(A8,orders!A:B,2,0),customers!A:F,6,0) -> Brazil | K8: =VLOOKUP(VLOOKUP(A8,orders!A:C,3,0),employees!A:B,2,0) -> Margaret Peacock
A9: 10250 | B9: 65 | C9: 16.8 | D9: 15 | E9: 0.15 | F9: =C9*D9*(1-E9) -> 214.2 | G9: =YEAR(VLOOKUP(A9,orders!A:D,4,0)) -> 2013 | H9: =MONTH(INDEX(orders!D:D,MATCH(A9, orders!A:A,0))) -> 7 | I9: =VLOOKUP(VLOOKUP(B9,products!A:F,6,0),categories!A:B,2,0) -> Condiments | J9: =VLOOKUP(VLOOKUP(A9,orders!A:B,2,0),customers!A:F,6,0) -> Brazil | K9: =VLOOKUP(VLOOKUP(A9,orders!A:C,3,0),employees!A:B,2,0) -> Margaret Peacock
A10: 10251 | B10: 22 | C10: 16.8 | D10: 6 | E10: 0.05 | F10: =C10*D10*(1-E10) -> 95.76 | G10: =YEAR(VLOOKUP(A10,orders!A:D,4,0)) -> 2013 | H10: =MONTH(INDEX(orders!D:D,MATCH(A10, orders!A:A,0))) -> 7 | I10: =VLOOKUP(VLOOKUP(B10,products!A:F,6,0),categories!A:B,2,0) -> Grains & Cereals | J10: =VLOOKUP(VLOOKUP(A10,orders!A:B,2,0),customers!A:F,6,0) -> France | K10: =VLOOKUP(VLOOKUP(A10,orders!A:C,3,0),employees!A:B,2,0) -> Janet Leverling
A11: 10251 | B11: 57 | C11: 15.6 | D11: 15 | E11: 0.05 | F11: =C11*D11*(1-E11) -> 222.3 | G11: =YEAR(VLOOKUP(A11,orders!A:D,4,0)) -> 2013 | H11: =MONTH(INDEX(orders!D:D,MATCH(A11, orders!A:A,0))) -> 7 | I11: =VLOOKUP(VLOOKUP(B11,products!A:F,6,0),categories!A:B,2,0) -> Grains & Cereals | J11: =VLOOKUP(VLOOKUP(A11,orders!A:B,2,0),customers!A:F,6,0) -> France | K11: =VLOOKUP(VLOOKUP(A11,orders!A:C,3,0),employees!A:B,2,0) -> Janet Leverling
A12: 10251 | B12: 65 | C12: 16.8 | D12: 20 | E12: 0 | F12: =C12*D12*(1-E12) -> 336 | G12: =YEAR(VLOOKUP(A12,orders!A:D,4,0)) -> 2013 | H12: =MONTH(INDEX(orders!D:D,MATCH(A12, orders!A:A,0))) -> 7 | I12: =VLOOKUP(VLOOKUP(B12,products!A:F,6,0),categories!A:B,2,0) -> Condiments | J12: =VLOOKUP(VLOOKUP(A12,orders!A:B,2,0),customers!A:F,6,0) -> France | K12: =VLOOKUP(VLOOKUP(A12,orders!A:C,3,0),employees!A:B,2,0) -> Janet Leverling
A13: 10252 | B13: 20 | C13: 64.8 | D13: 40 | E13: 0.05 | F13: =C13*D13*(1-E13) -> 2462.4 | G13: =YEAR(VLOOKUP(A13,orders!A:D,4,0)) -> 2013 | H13: =MONTH(INDEX(orders!D:D,MATCH(A13, orders!A:A,0))) -> 7 | I13: =VLOOKUP(VLOOKUP(B13,products!A:F,6,0),categories!A:B,2,0) -> Confections | J13: =VLOOKUP(VLOOKUP(A13,orders!A:B,2,0),customers!A:F,6,0) -> Belgium | K13: =VLOOKUP(VLOOKUP(A13,orders!A:C,3,0),employees!A:B,2,0) -> Margaret Peacock
... A2156: 11077 | B2156: 77 | C2156: 13 | D2156: 2 | E2156: 0 | F2156: =C2156*D2156*(1-E2156) -> 26 | G2156: =YEAR(VLOOKUP(A2156,orders!A:D,4,0)) -> 2015 | H2156: =MONTH(INDEX(orders!D:D,MATCH(A2156, orders!A:A,0))) -> 5 | I2156: =VLOOKUP(VLOOKUP(B2156,products!A:F,6,0),categories!A:B,2,0) -> Condiments | J2156: =VLOOKUP(VLOOKUP(A2156,orders!A:B,2,0),customers!A:F,6,0) -> USA | K2156: =VLOOKUP(VLOOKUP(A2156,orders!A:C,3,0),employees!A:B,2,0) -> Nancy Davolio
F2157: =SUM(F2:F2156) -> 1265793

Sheet customers
A1: customerID | B1: companyName | C1: contactName | D1: contactTitle | E1: city | F1: country
A2: ALFKI | B2: Alfreds Futterkiste | C2: Maria Anders | D2: Sales Representative | E2: Berlin | F2: Germany
A3: ANATR | B3: Ana Trujillo Emparedados y helados | C3: Ana Trujillo | D3: Owner | E3: Mexico City | F3: Mexico
A4: ANTON | B4: Antonio Moreno Taquería | C4: Antonio Moreno | D4: Owner | E4: Mexico City | F4: Mexico
A5: AROUT | B5: Around the Horn | C5: Thomas Hardy | D5: Sales Representative | E5: London | F5: UK
A6: BERGS | B6: Berglunds snabbköp | C6: Christina Berglund | D6: Order Administrator | E6: Luleå | F6: Sweden
A7: BLAUS | B7: Blauer See Delikatessen | C7: Hanna Moos | D7: Sales Representative | E7: Mannheim | F7: Germany
A8: BLONP | B8: Blondesddsl père et fils | C8: Frédérique Citeaux | D8: Marketing Manager | E8: Strasbourg | F8: France
A9: BOLID | B9: Bólido Comidas preparadas | C9: Martín Sommer | D9: Owner | E9: Madrid | F9: Spain
A10: BONAP | B10: Bon app' | C10: Laurence Lebihan | D10: Owner | E10: Marseille | F10: France
A11: BOTTM | B11: Bottom-Dollar Markets | C11: Elizabeth Lincoln | D11: Accounting Manager | E11: Tsawassen | F11: Canada
A12: BSBEV | B12: B's Beverages | C12: Victoria Ashworth | D12: Sales Representative | E12: London | F12: UK
... A92: WOLZA | B92: Wolski Zajazd | C92: Zbyszek Piestrzeniewicz | D92: Owner | E92: Warszawa | F92: Poland

Sheet products
A1: productID | B1: productName | C1: quantityPerUnit | D1: unitPrice | E1: discontinued | F1: categoryID
A2: 1 | B2: Chai | C2: 10 boxes x 20 bags | D2: 18 | E2: 0 | F2: 1
A3: 2 | B3: Chang | C3: 24 - 12 oz bottles | D3: 19 | E3: 0 | F3: 1
A4: 3 | B4: Aniseed Syrup | C4: 12 - 550 ml bottles | D4: 10 | E4: 0 | F4: 2
A5: 4 | B5: Chef Anton's Cajun Seasoning | C5: 48 - 6 oz jars | D5: 22 | E5: 0 | F5: 2
A6: 5 | B6: Chef Anton's Gumbo Mix | C6: 36 boxes | D6: 21.35 | E6: 1 | F6: 2
A7: 6 | B7: Grandma's Boysenberry Spread | C7: 12 - 8 oz jars | D7: 25 | E7: 0 | F7: 2
A8: 7 | B8: Uncle Bob's Organic Dried Pears | C8: 12 - 1 lb pkgs. | D8: 30 | E8: 0 | F8: 7
A9: 8 | B9: Northwoods Cranberry Sauce | C9: 12 - 12 oz jars | D9: 40 | E9: 0 | F9: 2
A10: 9 | B10: Mishi Kobe Niku | C10: 18 - 500 g pkgs. | D10: 97 | E10: 1 | F10: 6
A11: 10 | B11: Ikura | C11: 12 - 200 ml jars | D11: 31 | E11: 0 | F11: 8
A12: 11 | B12: Queso Cabrales | C12: 1 kg pkg. | D12: 21 | E12: 0 | F12: 4
A13: 12 | B13: Queso Manchego La Pastora | C13: 10 - 500 g pkgs. | D13: 38 | E13: 0 | F13: 4
... A78: 77 | B78: Original Frankfurter Grüne Soße | C78: 12 boxes | D78: 13 | E78: 0 | F78: 2

Sheet categories
A1: categoryID | B1: categoryName | C1: description
A2: 1 | B2: Beverages | C2: Soft drinks, coffees, teas, beers, and ales
A3: 2 | B3: Condiments | C3: Sweet and savory sauces, relishes, spreads, and seasonings
A4: 3 | B4: Confections | C4: Desserts, candies, and sweet breads
A5: 4 | B5: Dairy Products | C5: Cheeses
A6: 5 | B6: Grains & Cereals | C6: Breads, crackers, pasta, and cereal
A7: 6 | B7: Meat & Poultry | C7: Prepared meats
A8: 7 | B8: Produce | C8: Dried fruit and bean curd
A9: 8 | B9: Seafood | C9: Seaweed and fish

Sheet employees
A1: employeeID | B1: employeeName | C1: title | D1: city | E1: country | F1: reportsTo
A2: 1 | B2: Nancy Davolio | C2: Sales Representative | D2: New York | E2: USA | F2: 8
A3: 2 | B3: Andrew Fuller | C3: Vice President Sales | D3: New York | E3: USA
A4: 3 | B4: Janet Leverling | C4: Sales Representative | D4: New York | E4: USA | F4: 8
A5: 4 | B5: Margaret Peacock | C5: Sales Representative | D5: New York | E5: USA | F5: 8
A6: 5 | B6: Steven Buchanan | C6: Sales Manager | D6: London | E6: UK | F6: 2
A7: 6 | B7: Michael Suyama | C7: Sales Representative | D7: London | E7: UK | F7: 5
A8: 7 | B8: Robert King | C8: Sales Representative | D8: London | E8: UK | F8: 5
A9: 8 | B9: Laura Callahan | C9: Sales Manager | D9: New York | E9: USA | F9: 2
A10: 9 | B10: Anne Dodsworth | C10: Sales Representative | D10: London | E10: UK | F10: 5

Sheet shippers
A1: shipperID | B1: companyName
A2: 1 | B2: Speedy Express
A3: 2 | B3: United Package
A4: 3 | B4: Federal Shipping

Sheet Data_Page1
A1: Year | B1: Revenue | D1: Month | E1: Orders | G1: Category | H1: Revenue | J1: ProductB | K1: Revenue | M1: Country | N1: Revenue | P1: Employee | Q1: Revenue
A2: 2013 | B2: =SUMIF(order_details!G2:G2156,2013,order_details!F2:F2156) -> 208083.97 | D2: 1 | E2: =COUNTIF(order_details!H2:H2156,D2) -> 237 | G2: Beverages | H2: =SUMIF(order_details!I2:I2156,G2,order_details!F2:F2156) -> 267868.18 | J2: Côte de Blaye | K2: 141396 | M2: France | N2: =SUMIF(order_details!J$2:J$2156,M2,order_details!F$2:F$2156) -> 81358.322 | P2: Nancy Davolio | Q2: =SUMIF(order_details!K$2:K$2156,P2,order_details!F$2:F$2156) -> 192107.6
A3: 2014 | B3: =SUMIF(order_details!G2:G2156,2014,order_details!F2:F2156) -> 617085.2 | D3: 2 | E3: =COUNTIF(order_details!H3:H2157,D3) -> 201 | G3: Condiments | H3: =SUMIF(order_details!I3:I2157,G3,order_details!F3:F2157) -> 106047.09 | J3: Thüringer Rostbratwurst | K3: 80368 | M3: Germany | N3: =SUMIF(order_details!J$2:J$2156,M3,order_details!F$2:F$2156) -> 230284.63 | P3: Andrew Fuller | Q3: =SUMIF(order_details!K$2:K$2156,P3,order_details!F$2:F$2156) -> 166537.76
A4: 2015 | B4: =SUMIF(order_details!G2:G2156,2015,order_details!F2:F2156) -> 440623.87 | D4: 3 | E4: =COUNTIF(order_details!H4:H2158,D4) -> 255 | G4: Confections | H4: =SUMIF(order_details!I4:I2158,G4,order_details!F4:F2158) -> 167357.22 | J4: Raclette Courdavault | K4: 71155 | M4: USA | N4: =SUMIF(order_details!J$2:J$2156,M4,order_details!F$2:F$2156) -> 245584.61 | P4: Janet Leverling | Q4: =SUMIF(order_details!K$2:K$2156,P4,order_details!F$2:F$2156) -> 202812.84
D5: 4 | E5: =COUNTIF(order_details!H5:H2159,D5) -> 261 | G5: Dairy Products | H5: =SUMIF(order_details!I5:I2159,G5,order_details!F5:F2159) -> 234165.29 | J5: Camembert Pierrot | K5: 49827 | M5: Brazil | N5: =SUMIF(order_details!J$2:J$2156,M5,order_details!F$2:F$2156) -> 106925.78 | P5: Margaret Peacock | Q5: =SUMIF(order_details!K$2:K$2156,P5,order_details!F$2:F$2156) -> 232890.85
D6: 5 | E6: =COUNTIF(order_details!H6:H2160,D6) -> 155 | G6: Grains & Cereals | H6: =SUMIF(order_details!I6:I2160,G6,order_details!F6:F2160) -> 95646.588 | J6: Tarte au sucre | K6: 47234 | M6: UK | N6: =SUMIF(order_details!J$2:J$2156,M6,order_details!F$2:F$2156) -> 58971.31 | P6: Steven Buchanan | Q6: =SUMIF(order_details!K$2:K$2156,P6,order_details!F$2:F$2156) -> 68792.283
D7: 6 | E7: =COUNTIF(order_details!H7:H2161,D7) -> 76 | G7: Meat & Poultry | H7: =SUMIF(order_details!I7:I2161,G7,order_details!F7:F2161) -> 163022.36 | J7: Gnocchi di nonna Alice | K7: 42593 | M7: Canada | N7: =SUMIF(order_details!J$2:J$2156,M7,order_details!F$2:F$2156) -> 50196.29 | P7: Michael Suyama | Q7: =SUMIF(order_details!K$2:K$2156,P7,order_details!F$2:F$2156) -> 73913.13
D8: 7 | E8: =COUNTIF(order_details!H8:H2162,D8) -> 130 | G8: Produce | H8: =SUMIF(order_details!I8:I2162,G8,order_details!F8:F2162) -> 98121.18 | J8: Manjimup Dried Apples | K8: 41819 | M8: Austria | N8: =SUMIF(order_details!J$2:J$2156,M8,order_details!F$2:F$2156) -> 128003.84 | P8: Robert King | Q8: =SUMIF(order_details!K$2:K$2156,P8,order_details!F$2:F$2156) -> 124568.24
D9: 8 | E9: =COUNTIF(order_details!H9:H2163,D9) -> 153 | G9: Seafood | H9: =SUMIF(order_details!I9:I2163,G9,order_details!F9:F2163) -> 131184.74 | J9: Alice Mutton | K9: 32698 | M9: Sweden | N9: =SUMIF(order_details!J$2:J$2156,M9,order_details!F$2:F$2156) -> 54495.14 | P9: Laura Callahan | Q9: =SUMIF(order_details!K$2:K$2156,P9,order_details!F$2:F$2156) -> 126862.28
D10: 9 | E10: =COUNTIF(order_details!H10:H2164,D10) -> 152 | J10: Carnarvon Tigers | K10: 29171 | M10: Venezuela | N10: =SUMIF(order_details!J$2:J$2156,M10,order_details!F$2:F$2156) -> 56810.629 | P10: Anne Dodsworth | Q10: =SUMIF(order_details!K$2:K$2156,P10,order_details!F$2:F$2156) -> 77308.067
D11: 10 | E11: =COUNTIF(order_details!H11:H2165,D11) -> 179 | J11: Rössle Sauerkraut | K11: 25696 | M11: Mexico | N11: =SUMIF(order_details!J$2:J$2156,M11,order_details!F$2:F$2156) -> 23582.078
D12: 11 | E12: =COUNTIF(order_details!H12:H2166,D12) -> 155
D13: 12 | E13: =COUNTIF(order_details!H13:H2167,D13) -> 195

Sheet Pivot table 1
A5: Row Labels | B5: Sum of Revenue
A6: 2014 | B6: 835.2
A7: Grand Total | B7: 835.2
I16: 78

Sheet Dashboard_Page1
B4: Page 1: Sales& Revenue Overview
B6: Total Revenue | D6: Total Orders | F6: Total Customers
B7: =SUM(order_details!F2:F2156) -> 1265793 | D7: =COUNTA([1]order!A2:A1000) -> 999 | F7: =COUNTA(customers!A2:A1000) -> 91

Sheet Dashboard_Page2
B4: Page2: Product & Category Intelligence

Sheet Dashboard_Page3
B4: Page 3: Regional, Operational & People Performance
